test_add_delete_classification (__main__.TestClassifications) ... ERROR
test_filtering_classifications (__main__.TestClassifications) ... ERROR
test_get_all_classifications (__main__.TestClassifications) ... ERROR
test_add_delete_countries (__main__.TestCountries) ... ERROR
test_filtering_countries (__main__.TestCountries) ... ERROR
test_get_all_countries (__main__.TestCountries) ... ERROR
test_add_delete_meteorites (__main__.TestMeteorites) ... ERROR
test_filtering_meteorites (__main__.TestMeteorites) ... ERROR
test_get_all_meteorites (__main__.TestMeteorites) ... ERROR

======================================================================
ERROR: test_add_delete_classification (__main__.TestClassifications)
----------------------------------------------------------------------
Traceback (most recent call last):
  File "c:\python34\lib\site-packages\sqlalchemy\engine\base.py", line 2074, in _wrap_pool_connect
    return fn()
  File "c:\python34\lib\site-packages\sqlalchemy\pool.py", line 376, in connect
    return _ConnectionFairy._checkout(self)
  File "c:\python34\lib\site-packages\sqlalchemy\pool.py", line 713, in _checkout
    fairy = _ConnectionRecord.checkout(pool)
  File "c:\python34\lib\site-packages\sqlalchemy\pool.py", line 480, in checkout
    rec = pool._do_get()
  File "c:\python34\lib\site-packages\sqlalchemy\pool.py", line 1151, in _do_get
    return self._create_connection()
  File "c:\python34\lib\site-packages\sqlalchemy\pool.py", line 323, in _create_connection
    return _ConnectionRecord(self)
  File "c:\python34\lib\site-packages\sqlalchemy\pool.py", line 449, in __init__
    self.connection = self.__connect()
  File "c:\python34\lib\site-packages\sqlalchemy\pool.py", line 607, in __connect
    connection = self.__pool._invoke_creator(self)
  File "c:\python34\lib\site-packages\sqlalchemy\engine\strategies.py", line 97, in connect
    return dialect.connect(*cargs, **cparams)
  File "c:\python34\lib\site-packages\sqlalchemy\engine\default.py", line 385, in connect
    return self.dbapi.connect(*cargs, **cparams)
sqlite3.OperationalError: unable to open database file

The above exception was the direct cause of the following exception:

Traceback (most recent call last):
  File "app/tests.py", line 54, in setUp
    db.create_all()
  File "c:\python34\lib\site-packages\flask_sqlalchemy\__init__.py", line 972, in create_all
    self._execute_for_all_tables(app, bind, 'create_all')
  File "c:\python34\lib\site-packages\flask_sqlalchemy\__init__.py", line 964, in _execute_for_all_tables
    op(bind=self.get_engine(app, bind), **extra)
  File "c:\python34\lib\site-packages\sqlalchemy\sql\schema.py", line 3695, in create_all
    tables=tables)
  File "c:\python34\lib\site-packages\sqlalchemy\engine\base.py", line 1855, in _run_visitor
    with self._optional_conn_ctx_manager(connection) as conn:
  File "c:\python34\lib\contextlib.py", line 59, in __enter__
    return next(self.gen)
  File "c:\python34\lib\site-packages\sqlalchemy\engine\base.py", line 1848, in _optional_conn_ctx_manager
    with self.contextual_connect() as conn:
  File "c:\python34\lib\site-packages\sqlalchemy\engine\base.py", line 2039, in contextual_connect
    self._wrap_pool_connect(self.pool.connect, None),
  File "c:\python34\lib\site-packages\sqlalchemy\engine\base.py", line 2078, in _wrap_pool_connect
    e, dialect, self)
  File "c:\python34\lib\site-packages\sqlalchemy\engine\base.py", line 1405, in _handle_dbapi_exception_noconnection
    exc_info
  File "c:\python34\lib\site-packages\sqlalchemy\util\compat.py", line 200, in raise_from_cause
    reraise(type(exception), exception, tb=exc_tb, cause=cause)
  File "c:\python34\lib\site-packages\sqlalchemy\util\compat.py", line 183, in reraise
    raise value.with_traceback(tb)
  File "c:\python34\lib\site-packages\sqlalchemy\engine\base.py", line 2074, in _wrap_pool_connect
    return fn()
  File "c:\python34\lib\site-packages\sqlalchemy\pool.py", line 376, in connect
    return _ConnectionFairy._checkout(self)
  File "c:\python34\lib\site-packages\sqlalchemy\pool.py", line 713, in _checkout
    fairy = _ConnectionRecord.checkout(pool)
  File "c:\python34\lib\site-packages\sqlalchemy\pool.py", line 480, in checkout
    rec = pool._do_get()
  File "c:\python34\lib\site-packages\sqlalchemy\pool.py", line 1151, in _do_get
    return self._create_connection()
  File "c:\python34\lib\site-packages\sqlalchemy\pool.py", line 323, in _create_connection
    return _ConnectionRecord(self)
  File "c:\python34\lib\site-packages\sqlalchemy\pool.py", line 449, in __init__
    self.connection = self.__connect()
  File "c:\python34\lib\site-packages\sqlalchemy\pool.py", line 607, in __connect
    connection = self.__pool._invoke_creator(self)
  File "c:\python34\lib\site-packages\sqlalchemy\engine\strategies.py", line 97, in connect
    return dialect.connect(*cargs, **cparams)
  File "c:\python34\lib\site-packages\sqlalchemy\engine\default.py", line 385, in connect
    return self.dbapi.connect(*cargs, **cparams)
sqlalchemy.exc.OperationalError: (sqlite3.OperationalError) unable to open database file

======================================================================
ERROR: test_filtering_classifications (__main__.TestClassifications)
----------------------------------------------------------------------
Traceback (most recent call last):
  File "c:\python34\lib\site-packages\sqlalchemy\engine\base.py", line 2074, in _wrap_pool_connect
    return fn()
  File "c:\python34\lib\site-packages\sqlalchemy\pool.py", line 376, in connect
    return _ConnectionFairy._checkout(self)
  File "c:\python34\lib\site-packages\sqlalchemy\pool.py", line 713, in _checkout
    fairy = _ConnectionRecord.checkout(pool)
  File "c:\python34\lib\site-packages\sqlalchemy\pool.py", line 480, in checkout
    rec = pool._do_get()
  File "c:\python34\lib\site-packages\sqlalchemy\pool.py", line 1151, in _do_get
    return self._create_connection()
  File "c:\python34\lib\site-packages\sqlalchemy\pool.py", line 323, in _create_connection
    return _ConnectionRecord(self)
  File "c:\python34\lib\site-packages\sqlalchemy\pool.py", line 449, in __init__
    self.connection = self.__connect()
  File "c:\python34\lib\site-packages\sqlalchemy\pool.py", line 607, in __connect
    connection = self.__pool._invoke_creator(self)
  File "c:\python34\lib\site-packages\sqlalchemy\engine\strategies.py", line 97, in connect
    return dialect.connect(*cargs, **cparams)
  File "c:\python34\lib\site-packages\sqlalchemy\engine\default.py", line 385, in connect
    return self.dbapi.connect(*cargs, **cparams)
sqlite3.OperationalError: unable to open database file

The above exception was the direct cause of the following exception:

Traceback (most recent call last):
  File "app/tests.py", line 54, in setUp
    db.create_all()
  File "c:\python34\lib\site-packages\flask_sqlalchemy\__init__.py", line 972, in create_all
    self._execute_for_all_tables(app, bind, 'create_all')
  File "c:\python34\lib\site-packages\flask_sqlalchemy\__init__.py", line 964, in _execute_for_all_tables
    op(bind=self.get_engine(app, bind), **extra)
  File "c:\python34\lib\site-packages\sqlalchemy\sql\schema.py", line 3695, in create_all
    tables=tables)
  File "c:\python34\lib\site-packages\sqlalchemy\engine\base.py", line 1855, in _run_visitor
    with self._optional_conn_ctx_manager(connection) as conn:
  File "c:\python34\lib\contextlib.py", line 59, in __enter__
    return next(self.gen)
  File "c:\python34\lib\site-packages\sqlalchemy\engine\base.py", line 1848, in _optional_conn_ctx_manager
    with self.contextual_connect() as conn:
  File "c:\python34\lib\site-packages\sqlalchemy\engine\base.py", line 2039, in contextual_connect
    self._wrap_pool_connect(self.pool.connect, None),
  File "c:\python34\lib\site-packages\sqlalchemy\engine\base.py", line 2078, in _wrap_pool_connect
    e, dialect, self)
  File "c:\python34\lib\site-packages\sqlalchemy\engine\base.py", line 1405, in _handle_dbapi_exception_noconnection
    exc_info
  File "c:\python34\lib\site-packages\sqlalchemy\util\compat.py", line 200, in raise_from_cause
    reraise(type(exception), exception, tb=exc_tb, cause=cause)
  File "c:\python34\lib\site-packages\sqlalchemy\util\compat.py", line 183, in reraise
    raise value.with_traceback(tb)
  File "c:\python34\lib\site-packages\sqlalchemy\engine\base.py", line 2074, in _wrap_pool_connect
    return fn()
  File "c:\python34\lib\site-packages\sqlalchemy\pool.py", line 376, in connect
    return _ConnectionFairy._checkout(self)
  File "c:\python34\lib\site-packages\sqlalchemy\pool.py", line 713, in _checkout
    fairy = _ConnectionRecord.checkout(pool)
  File "c:\python34\lib\site-packages\sqlalchemy\pool.py", line 480, in checkout
    rec = pool._do_get()
  File "c:\python34\lib\site-packages\sqlalchemy\pool.py", line 1151, in _do_get
    return self._create_connection()
  File "c:\python34\lib\site-packages\sqlalchemy\pool.py", line 323, in _create_connection
    return _ConnectionRecord(self)
  File "c:\python34\lib\site-packages\sqlalchemy\pool.py", line 449, in __init__
    self.connection = self.__connect()
  File "c:\python34\lib\site-packages\sqlalchemy\pool.py", line 607, in __connect
    connection = self.__pool._invoke_creator(self)
  File "c:\python34\lib\site-packages\sqlalchemy\engine\strategies.py", line 97, in connect
    return dialect.connect(*cargs, **cparams)
  File "c:\python34\lib\site-packages\sqlalchemy\engine\default.py", line 385, in connect
    return self.dbapi.connect(*cargs, **cparams)
sqlalchemy.exc.OperationalError: (sqlite3.OperationalError) unable to open database file

======================================================================
ERROR: test_get_all_classifications (__main__.TestClassifications)
----------------------------------------------------------------------
Traceback (most recent call last):
  File "c:\python34\lib\site-packages\sqlalchemy\engine\base.py", line 2074, in _wrap_pool_connect
    return fn()
  File "c:\python34\lib\site-packages\sqlalchemy\pool.py", line 376, in connect
    return _ConnectionFairy._checkout(self)
  File "c:\python34\lib\site-packages\sqlalchemy\pool.py", line 713, in _checkout
    fairy = _ConnectionRecord.checkout(pool)
  File "c:\python34\lib\site-packages\sqlalchemy\pool.py", line 480, in checkout
    rec = pool._do_get()
  File "c:\python34\lib\site-packages\sqlalchemy\pool.py", line 1151, in _do_get
    return self._create_connection()
  File "c:\python34\lib\site-packages\sqlalchemy\pool.py", line 323, in _create_connection
    return _ConnectionRecord(self)
  File "c:\python34\lib\site-packages\sqlalchemy\pool.py", line 449, in __init__
    self.connection = self.__connect()
  File "c:\python34\lib\site-packages\sqlalchemy\pool.py", line 607, in __connect
    connection = self.__pool._invoke_creator(self)
  File "c:\python34\lib\site-packages\sqlalchemy\engine\strategies.py", line 97, in connect
    return dialect.connect(*cargs, **cparams)
  File "c:\python34\lib\site-packages\sqlalchemy\engine\default.py", line 385, in connect
    return self.dbapi.connect(*cargs, **cparams)
sqlite3.OperationalError: unable to open database file

The above exception was the direct cause of the following exception:

Traceback (most recent call last):
  File "app/tests.py", line 54, in setUp
    db.create_all()
  File "c:\python34\lib\site-packages\flask_sqlalchemy\__init__.py", line 972, in create_all
    self._execute_for_all_tables(app, bind, 'create_all')
  File "c:\python34\lib\site-packages\flask_sqlalchemy\__init__.py", line 964, in _execute_for_all_tables
    op(bind=self.get_engine(app, bind), **extra)
  File "c:\python34\lib\site-packages\sqlalchemy\sql\schema.py", line 3695, in create_all
    tables=tables)
  File "c:\python34\lib\site-packages\sqlalchemy\engine\base.py", line 1855, in _run_visitor
    with self._optional_conn_ctx_manager(connection) as conn:
  File "c:\python34\lib\contextlib.py", line 59, in __enter__
    return next(self.gen)
  File "c:\python34\lib\site-packages\sqlalchemy\engine\base.py", line 1848, in _optional_conn_ctx_manager
    with self.contextual_connect() as conn:
  File "c:\python34\lib\site-packages\sqlalchemy\engine\base.py", line 2039, in contextual_connect
    self._wrap_pool_connect(self.pool.connect, None),
  File "c:\python34\lib\site-packages\sqlalchemy\engine\base.py", line 2078, in _wrap_pool_connect
    e, dialect, self)
  File "c:\python34\lib\site-packages\sqlalchemy\engine\base.py", line 1405, in _handle_dbapi_exception_noconnection
    exc_info
  File "c:\python34\lib\site-packages\sqlalchemy\util\compat.py", line 200, in raise_from_cause
    reraise(type(exception), exception, tb=exc_tb, cause=cause)
  File "c:\python34\lib\site-packages\sqlalchemy\util\compat.py", line 183, in reraise
    raise value.with_traceback(tb)
  File "c:\python34\lib\site-packages\sqlalchemy\engine\base.py", line 2074, in _wrap_pool_connect
    return fn()
  File "c:\python34\lib\site-packages\sqlalchemy\pool.py", line 376, in connect
    return _ConnectionFairy._checkout(self)
  File "c:\python34\lib\site-packages\sqlalchemy\pool.py", line 713, in _checkout
    fairy = _ConnectionRecord.checkout(pool)
  File "c:\python34\lib\site-packages\sqlalchemy\pool.py", line 480, in checkout
    rec = pool._do_get()
  File "c:\python34\lib\site-packages\sqlalchemy\pool.py", line 1151, in _do_get
    return self._create_connection()
  File "c:\python34\lib\site-packages\sqlalchemy\pool.py", line 323, in _create_connection
    return _ConnectionRecord(self)
  File "c:\python34\lib\site-packages\sqlalchemy\pool.py", line 449, in __init__
    self.connection = self.__connect()
  File "c:\python34\lib\site-packages\sqlalchemy\pool.py", line 607, in __connect
    connection = self.__pool._invoke_creator(self)
  File "c:\python34\lib\site-packages\sqlalchemy\engine\strategies.py", line 97, in connect
    return dialect.connect(*cargs, **cparams)
  File "c:\python34\lib\site-packages\sqlalchemy\engine\default.py", line 385, in connect
    return self.dbapi.connect(*cargs, **cparams)
sqlalchemy.exc.OperationalError: (sqlite3.OperationalError) unable to open database file

======================================================================
ERROR: test_add_delete_countries (__main__.TestCountries)
----------------------------------------------------------------------
Traceback (most recent call last):
  File "c:\python34\lib\site-packages\sqlalchemy\engine\base.py", line 2074, in _wrap_pool_connect
    return fn()
  File "c:\python34\lib\site-packages\sqlalchemy\pool.py", line 376, in connect
    return _ConnectionFairy._checkout(self)
  File "c:\python34\lib\site-packages\sqlalchemy\pool.py", line 713, in _checkout
    fairy = _ConnectionRecord.checkout(pool)
  File "c:\python34\lib\site-packages\sqlalchemy\pool.py", line 480, in checkout
    rec = pool._do_get()
  File "c:\python34\lib\site-packages\sqlalchemy\pool.py", line 1151, in _do_get
    return self._create_connection()
  File "c:\python34\lib\site-packages\sqlalchemy\pool.py", line 323, in _create_connection
    return _ConnectionRecord(self)
  File "c:\python34\lib\site-packages\sqlalchemy\pool.py", line 449, in __init__
    self.connection = self.__connect()
  File "c:\python34\lib\site-packages\sqlalchemy\pool.py", line 607, in __connect
    connection = self.__pool._invoke_creator(self)
  File "c:\python34\lib\site-packages\sqlalchemy\engine\strategies.py", line 97, in connect
    return dialect.connect(*cargs, **cparams)
  File "c:\python34\lib\site-packages\sqlalchemy\engine\default.py", line 385, in connect
    return self.dbapi.connect(*cargs, **cparams)
sqlite3.OperationalError: unable to open database file

The above exception was the direct cause of the following exception:

Traceback (most recent call last):
  File "app/tests.py", line 97, in setUp
    db.create_all()
  File "c:\python34\lib\site-packages\flask_sqlalchemy\__init__.py", line 972, in create_all
    self._execute_for_all_tables(app, bind, 'create_all')
  File "c:\python34\lib\site-packages\flask_sqlalchemy\__init__.py", line 964, in _execute_for_all_tables
    op(bind=self.get_engine(app, bind), **extra)
  File "c:\python34\lib\site-packages\sqlalchemy\sql\schema.py", line 3695, in create_all
    tables=tables)
  File "c:\python34\lib\site-packages\sqlalchemy\engine\base.py", line 1855, in _run_visitor
    with self._optional_conn_ctx_manager(connection) as conn:
  File "c:\python34\lib\contextlib.py", line 59, in __enter__
    return next(self.gen)
  File "c:\python34\lib\site-packages\sqlalchemy\engine\base.py", line 1848, in _optional_conn_ctx_manager
    with self.contextual_connect() as conn:
  File "c:\python34\lib\site-packages\sqlalchemy\engine\base.py", line 2039, in contextual_connect
    self._wrap_pool_connect(self.pool.connect, None),
  File "c:\python34\lib\site-packages\sqlalchemy\engine\base.py", line 2078, in _wrap_pool_connect
    e, dialect, self)
  File "c:\python34\lib\site-packages\sqlalchemy\engine\base.py", line 1405, in _handle_dbapi_exception_noconnection
    exc_info
  File "c:\python34\lib\site-packages\sqlalchemy\util\compat.py", line 200, in raise_from_cause
    reraise(type(exception), exception, tb=exc_tb, cause=cause)
  File "c:\python34\lib\site-packages\sqlalchemy\util\compat.py", line 183, in reraise
    raise value.with_traceback(tb)
  File "c:\python34\lib\site-packages\sqlalchemy\engine\base.py", line 2074, in _wrap_pool_connect
    return fn()
  File "c:\python34\lib\site-packages\sqlalchemy\pool.py", line 376, in connect
    return _ConnectionFairy._checkout(self)
  File "c:\python34\lib\site-packages\sqlalchemy\pool.py", line 713, in _checkout
    fairy = _ConnectionRecord.checkout(pool)
  File "c:\python34\lib\site-packages\sqlalchemy\pool.py", line 480, in checkout
    rec = pool._do_get()
  File "c:\python34\lib\site-packages\sqlalchemy\pool.py", line 1151, in _do_get
    return self._create_connection()
  File "c:\python34\lib\site-packages\sqlalchemy\pool.py", line 323, in _create_connection
    return _ConnectionRecord(self)
  File "c:\python34\lib\site-packages\sqlalchemy\pool.py", line 449, in __init__
    self.connection = self.__connect()
  File "c:\python34\lib\site-packages\sqlalchemy\pool.py", line 607, in __connect
    connection = self.__pool._invoke_creator(self)
  File "c:\python34\lib\site-packages\sqlalchemy\engine\strategies.py", line 97, in connect
    return dialect.connect(*cargs, **cparams)
  File "c:\python34\lib\site-packages\sqlalchemy\engine\default.py", line 385, in connect
    return self.dbapi.connect(*cargs, **cparams)
sqlalchemy.exc.OperationalError: (sqlite3.OperationalError) unable to open database file

======================================================================
ERROR: test_filtering_countries (__main__.TestCountries)
----------------------------------------------------------------------
Traceback (most recent call last):
  File "c:\python34\lib\site-packages\sqlalchemy\engine\base.py", line 2074, in _wrap_pool_connect
    return fn()
  File "c:\python34\lib\site-packages\sqlalchemy\pool.py", line 376, in connect
    return _ConnectionFairy._checkout(self)
  File "c:\python34\lib\site-packages\sqlalchemy\pool.py", line 713, in _checkout
    fairy = _ConnectionRecord.checkout(pool)
  File "c:\python34\lib\site-packages\sqlalchemy\pool.py", line 480, in checkout
    rec = pool._do_get()
  File "c:\python34\lib\site-packages\sqlalchemy\pool.py", line 1151, in _do_get
    return self._create_connection()
  File "c:\python34\lib\site-packages\sqlalchemy\pool.py", line 323, in _create_connection
    return _ConnectionRecord(self)
  File "c:\python34\lib\site-packages\sqlalchemy\pool.py", line 449, in __init__
    self.connection = self.__connect()
  File "c:\python34\lib\site-packages\sqlalchemy\pool.py", line 607, in __connect
    connection = self.__pool._invoke_creator(self)
  File "c:\python34\lib\site-packages\sqlalchemy\engine\strategies.py", line 97, in connect
    return dialect.connect(*cargs, **cparams)
  File "c:\python34\lib\site-packages\sqlalchemy\engine\default.py", line 385, in connect
    return self.dbapi.connect(*cargs, **cparams)
sqlite3.OperationalError: unable to open database file

The above exception was the direct cause of the following exception:

Traceback (most recent call last):
  File "app/tests.py", line 97, in setUp
    db.create_all()
  File "c:\python34\lib\site-packages\flask_sqlalchemy\__init__.py", line 972, in create_all
    self._execute_for_all_tables(app, bind, 'create_all')
  File "c:\python34\lib\site-packages\flask_sqlalchemy\__init__.py", line 964, in _execute_for_all_tables
    op(bind=self.get_engine(app, bind), **extra)
  File "c:\python34\lib\site-packages\sqlalchemy\sql\schema.py", line 3695, in create_all
    tables=tables)
  File "c:\python34\lib\site-packages\sqlalchemy\engine\base.py", line 1855, in _run_visitor
    with self._optional_conn_ctx_manager(connection) as conn:
  File "c:\python34\lib\contextlib.py", line 59, in __enter__
    return next(self.gen)
  File "c:\python34\lib\site-packages\sqlalchemy\engine\base.py", line 1848, in _optional_conn_ctx_manager
    with self.contextual_connect() as conn:
  File "c:\python34\lib\site-packages\sqlalchemy\engine\base.py", line 2039, in contextual_connect
    self._wrap_pool_connect(self.pool.connect, None),
  File "c:\python34\lib\site-packages\sqlalchemy\engine\base.py", line 2078, in _wrap_pool_connect
    e, dialect, self)
  File "c:\python34\lib\site-packages\sqlalchemy\engine\base.py", line 1405, in _handle_dbapi_exception_noconnection
    exc_info
  File "c:\python34\lib\site-packages\sqlalchemy\util\compat.py", line 200, in raise_from_cause
    reraise(type(exception), exception, tb=exc_tb, cause=cause)
  File "c:\python34\lib\site-packages\sqlalchemy\util\compat.py", line 183, in reraise
    raise value.with_traceback(tb)
  File "c:\python34\lib\site-packages\sqlalchemy\engine\base.py", line 2074, in _wrap_pool_connect
    return fn()
  File "c:\python34\lib\site-packages\sqlalchemy\pool.py", line 376, in connect
    return _ConnectionFairy._checkout(self)
  File "c:\python34\lib\site-packages\sqlalchemy\pool.py", line 713, in _checkout
    fairy = _ConnectionRecord.checkout(pool)
  File "c:\python34\lib\site-packages\sqlalchemy\pool.py", line 480, in checkout
    rec = pool._do_get()
  File "c:\python34\lib\site-packages\sqlalchemy\pool.py", line 1151, in _do_get
    return self._create_connection()
  File "c:\python34\lib\site-packages\sqlalchemy\pool.py", line 323, in _create_connection
    return _ConnectionRecord(self)
  File "c:\python34\lib\site-packages\sqlalchemy\pool.py", line 449, in __init__
    self.connection = self.__connect()
  File "c:\python34\lib\site-packages\sqlalchemy\pool.py", line 607, in __connect
    connection = self.__pool._invoke_creator(self)
  File "c:\python34\lib\site-packages\sqlalchemy\engine\strategies.py", line 97, in connect
    return dialect.connect(*cargs, **cparams)
  File "c:\python34\lib\site-packages\sqlalchemy\engine\default.py", line 385, in connect
    return self.dbapi.connect(*cargs, **cparams)
sqlalchemy.exc.OperationalError: (sqlite3.OperationalError) unable to open database file

======================================================================
ERROR: test_get_all_countries (__main__.TestCountries)
----------------------------------------------------------------------
Traceback (most recent call last):
  File "c:\python34\lib\site-packages\sqlalchemy\engine\base.py", line 2074, in _wrap_pool_connect
    return fn()
  File "c:\python34\lib\site-packages\sqlalchemy\pool.py", line 376, in connect
    return _ConnectionFairy._checkout(self)
  File "c:\python34\lib\site-packages\sqlalchemy\pool.py", line 713, in _checkout
    fairy = _ConnectionRecord.checkout(pool)
  File "c:\python34\lib\site-packages\sqlalchemy\pool.py", line 480, in checkout
    rec = pool._do_get()
  File "c:\python34\lib\site-packages\sqlalchemy\pool.py", line 1151, in _do_get
    return self._create_connection()
  File "c:\python34\lib\site-packages\sqlalchemy\pool.py", line 323, in _create_connection
    return _ConnectionRecord(self)
  File "c:\python34\lib\site-packages\sqlalchemy\pool.py", line 449, in __init__
    self.connection = self.__connect()
  File "c:\python34\lib\site-packages\sqlalchemy\pool.py", line 607, in __connect
    connection = self.__pool._invoke_creator(self)
  File "c:\python34\lib\site-packages\sqlalchemy\engine\strategies.py", line 97, in connect
    return dialect.connect(*cargs, **cparams)
  File "c:\python34\lib\site-packages\sqlalchemy\engine\default.py", line 385, in connect
    return self.dbapi.connect(*cargs, **cparams)
sqlite3.OperationalError: unable to open database file

The above exception was the direct cause of the following exception:

Traceback (most recent call last):
  File "app/tests.py", line 97, in setUp
    db.create_all()
  File "c:\python34\lib\site-packages\flask_sqlalchemy\__init__.py", line 972, in create_all
    self._execute_for_all_tables(app, bind, 'create_all')
  File "c:\python34\lib\site-packages\flask_sqlalchemy\__init__.py", line 964, in _execute_for_all_tables
    op(bind=self.get_engine(app, bind), **extra)
  File "c:\python34\lib\site-packages\sqlalchemy\sql\schema.py", line 3695, in create_all
    tables=tables)
  File "c:\python34\lib\site-packages\sqlalchemy\engine\base.py", line 1855, in _run_visitor
    with self._optional_conn_ctx_manager(connection) as conn:
  File "c:\python34\lib\contextlib.py", line 59, in __enter__
    return next(self.gen)
  File "c:\python34\lib\site-packages\sqlalchemy\engine\base.py", line 1848, in _optional_conn_ctx_manager
    with self.contextual_connect() as conn:
  File "c:\python34\lib\site-packages\sqlalchemy\engine\base.py", line 2039, in contextual_connect
    self._wrap_pool_connect(self.pool.connect, None),
  File "c:\python34\lib\site-packages\sqlalchemy\engine\base.py", line 2078, in _wrap_pool_connect
    e, dialect, self)
  File "c:\python34\lib\site-packages\sqlalchemy\engine\base.py", line 1405, in _handle_dbapi_exception_noconnection
    exc_info
  File "c:\python34\lib\site-packages\sqlalchemy\util\compat.py", line 200, in raise_from_cause
    reraise(type(exception), exception, tb=exc_tb, cause=cause)
  File "c:\python34\lib\site-packages\sqlalchemy\util\compat.py", line 183, in reraise
    raise value.with_traceback(tb)
  File "c:\python34\lib\site-packages\sqlalchemy\engine\base.py", line 2074, in _wrap_pool_connect
    return fn()
  File "c:\python34\lib\site-packages\sqlalchemy\pool.py", line 376, in connect
    return _ConnectionFairy._checkout(self)
  File "c:\python34\lib\site-packages\sqlalchemy\pool.py", line 713, in _checkout
    fairy = _ConnectionRecord.checkout(pool)
  File "c:\python34\lib\site-packages\sqlalchemy\pool.py", line 480, in checkout
    rec = pool._do_get()
  File "c:\python34\lib\site-packages\sqlalchemy\pool.py", line 1151, in _do_get
    return self._create_connection()
  File "c:\python34\lib\site-packages\sqlalchemy\pool.py", line 323, in _create_connection
    return _ConnectionRecord(self)
  File "c:\python34\lib\site-packages\sqlalchemy\pool.py", line 449, in __init__
    self.connection = self.__connect()
  File "c:\python34\lib\site-packages\sqlalchemy\pool.py", line 607, in __connect
    connection = self.__pool._invoke_creator(self)
  File "c:\python34\lib\site-packages\sqlalchemy\engine\strategies.py", line 97, in connect
    return dialect.connect(*cargs, **cparams)
  File "c:\python34\lib\site-packages\sqlalchemy\engine\default.py", line 385, in connect
    return self.dbapi.connect(*cargs, **cparams)
sqlalchemy.exc.OperationalError: (sqlite3.OperationalError) unable to open database file

======================================================================
ERROR: test_add_delete_meteorites (__main__.TestMeteorites)
----------------------------------------------------------------------
Traceback (most recent call last):
  File "c:\python34\lib\site-packages\sqlalchemy\engine\base.py", line 2074, in _wrap_pool_connect
    return fn()
  File "c:\python34\lib\site-packages\sqlalchemy\pool.py", line 376, in connect
    return _ConnectionFairy._checkout(self)
  File "c:\python34\lib\site-packages\sqlalchemy\pool.py", line 713, in _checkout
    fairy = _ConnectionRecord.checkout(pool)
  File "c:\python34\lib\site-packages\sqlalchemy\pool.py", line 480, in checkout
    rec = pool._do_get()
  File "c:\python34\lib\site-packages\sqlalchemy\pool.py", line 1151, in _do_get
    return self._create_connection()
  File "c:\python34\lib\site-packages\sqlalchemy\pool.py", line 323, in _create_connection
    return _ConnectionRecord(self)
  File "c:\python34\lib\site-packages\sqlalchemy\pool.py", line 449, in __init__
    self.connection = self.__connect()
  File "c:\python34\lib\site-packages\sqlalchemy\pool.py", line 607, in __connect
    connection = self.__pool._invoke_creator(self)
  File "c:\python34\lib\site-packages\sqlalchemy\engine\strategies.py", line 97, in connect
    return dialect.connect(*cargs, **cparams)
  File "c:\python34\lib\site-packages\sqlalchemy\engine\default.py", line 385, in connect
    return self.dbapi.connect(*cargs, **cparams)
sqlite3.OperationalError: unable to open database file

The above exception was the direct cause of the following exception:

Traceback (most recent call last):
  File "app/tests.py", line 12, in setUp
    db.create_all()
  File "c:\python34\lib\site-packages\flask_sqlalchemy\__init__.py", line 972, in create_all
    self._execute_for_all_tables(app, bind, 'create_all')
  File "c:\python34\lib\site-packages\flask_sqlalchemy\__init__.py", line 964, in _execute_for_all_tables
    op(bind=self.get_engine(app, bind), **extra)
  File "c:\python34\lib\site-packages\sqlalchemy\sql\schema.py", line 3695, in create_all
    tables=tables)
  File "c:\python34\lib\site-packages\sqlalchemy\engine\base.py", line 1855, in _run_visitor
    with self._optional_conn_ctx_manager(connection) as conn:
  File "c:\python34\lib\contextlib.py", line 59, in __enter__
    return next(self.gen)
  File "c:\python34\lib\site-packages\sqlalchemy\engine\base.py", line 1848, in _optional_conn_ctx_manager
    with self.contextual_connect() as conn:
  File "c:\python34\lib\site-packages\sqlalchemy\engine\base.py", line 2039, in contextual_connect
    self._wrap_pool_connect(self.pool.connect, None),
  File "c:\python34\lib\site-packages\sqlalchemy\engine\base.py", line 2078, in _wrap_pool_connect
    e, dialect, self)
  File "c:\python34\lib\site-packages\sqlalchemy\engine\base.py", line 1405, in _handle_dbapi_exception_noconnection
    exc_info
  File "c:\python34\lib\site-packages\sqlalchemy\util\compat.py", line 200, in raise_from_cause
    reraise(type(exception), exception, tb=exc_tb, cause=cause)
  File "c:\python34\lib\site-packages\sqlalchemy\util\compat.py", line 183, in reraise
    raise value.with_traceback(tb)
  File "c:\python34\lib\site-packages\sqlalchemy\engine\base.py", line 2074, in _wrap_pool_connect
    return fn()
  File "c:\python34\lib\site-packages\sqlalchemy\pool.py", line 376, in connect
    return _ConnectionFairy._checkout(self)
  File "c:\python34\lib\site-packages\sqlalchemy\pool.py", line 713, in _checkout
    fairy = _ConnectionRecord.checkout(pool)
  File "c:\python34\lib\site-packages\sqlalchemy\pool.py", line 480, in checkout
    rec = pool._do_get()
  File "c:\python34\lib\site-packages\sqlalchemy\pool.py", line 1151, in _do_get
    return self._create_connection()
  File "c:\python34\lib\site-packages\sqlalchemy\pool.py", line 323, in _create_connection
    return _ConnectionRecord(self)
  File "c:\python34\lib\site-packages\sqlalchemy\pool.py", line 449, in __init__
    self.connection = self.__connect()
  File "c:\python34\lib\site-packages\sqlalchemy\pool.py", line 607, in __connect
    connection = self.__pool._invoke_creator(self)
  File "c:\python34\lib\site-packages\sqlalchemy\engine\strategies.py", line 97, in connect
    return dialect.connect(*cargs, **cparams)
  File "c:\python34\lib\site-packages\sqlalchemy\engine\default.py", line 385, in connect
    return self.dbapi.connect(*cargs, **cparams)
sqlalchemy.exc.OperationalError: (sqlite3.OperationalError) unable to open database file

======================================================================
ERROR: test_filtering_meteorites (__main__.TestMeteorites)
----------------------------------------------------------------------
Traceback (most recent call last):
  File "c:\python34\lib\site-packages\sqlalchemy\engine\base.py", line 2074, in _wrap_pool_connect
    return fn()
  File "c:\python34\lib\site-packages\sqlalchemy\pool.py", line 376, in connect
    return _ConnectionFairy._checkout(self)
  File "c:\python34\lib\site-packages\sqlalchemy\pool.py", line 713, in _checkout
    fairy = _ConnectionRecord.checkout(pool)
  File "c:\python34\lib\site-packages\sqlalchemy\pool.py", line 480, in checkout
    rec = pool._do_get()
  File "c:\python34\lib\site-packages\sqlalchemy\pool.py", line 1151, in _do_get
    return self._create_connection()
  File "c:\python34\lib\site-packages\sqlalchemy\pool.py", line 323, in _create_connection
    return _ConnectionRecord(self)
  File "c:\python34\lib\site-packages\sqlalchemy\pool.py", line 449, in __init__
    self.connection = self.__connect()
  File "c:\python34\lib\site-packages\sqlalchemy\pool.py", line 607, in __connect
    connection = self.__pool._invoke_creator(self)
  File "c:\python34\lib\site-packages\sqlalchemy\engine\strategies.py", line 97, in connect
    return dialect.connect(*cargs, **cparams)
  File "c:\python34\lib\site-packages\sqlalchemy\engine\default.py", line 385, in connect
    return self.dbapi.connect(*cargs, **cparams)
sqlite3.OperationalError: unable to open database file

The above exception was the direct cause of the following exception:

Traceback (most recent call last):
  File "app/tests.py", line 12, in setUp
    db.create_all()
  File "c:\python34\lib\site-packages\flask_sqlalchemy\__init__.py", line 972, in create_all
    self._execute_for_all_tables(app, bind, 'create_all')
  File "c:\python34\lib\site-packages\flask_sqlalchemy\__init__.py", line 964, in _execute_for_all_tables
    op(bind=self.get_engine(app, bind), **extra)
  File "c:\python34\lib\site-packages\sqlalchemy\sql\schema.py", line 3695, in create_all
    tables=tables)
  File "c:\python34\lib\site-packages\sqlalchemy\engine\base.py", line 1855, in _run_visitor
    with self._optional_conn_ctx_manager(connection) as conn:
  File "c:\python34\lib\contextlib.py", line 59, in __enter__
    return next(self.gen)
  File "c:\python34\lib\site-packages\sqlalchemy\engine\base.py", line 1848, in _optional_conn_ctx_manager
    with self.contextual_connect() as conn:
  File "c:\python34\lib\site-packages\sqlalchemy\engine\base.py", line 2039, in contextual_connect
    self._wrap_pool_connect(self.pool.connect, None),
  File "c:\python34\lib\site-packages\sqlalchemy\engine\base.py", line 2078, in _wrap_pool_connect
    e, dialect, self)
  File "c:\python34\lib\site-packages\sqlalchemy\engine\base.py", line 1405, in _handle_dbapi_exception_noconnection
    exc_info
  File "c:\python34\lib\site-packages\sqlalchemy\util\compat.py", line 200, in raise_from_cause
    reraise(type(exception), exception, tb=exc_tb, cause=cause)
  File "c:\python34\lib\site-packages\sqlalchemy\util\compat.py", line 183, in reraise
    raise value.with_traceback(tb)
  File "c:\python34\lib\site-packages\sqlalchemy\engine\base.py", line 2074, in _wrap_pool_connect
    return fn()
  File "c:\python34\lib\site-packages\sqlalchemy\pool.py", line 376, in connect
    return _ConnectionFairy._checkout(self)
  File "c:\python34\lib\site-packages\sqlalchemy\pool.py", line 713, in _checkout
    fairy = _ConnectionRecord.checkout(pool)
  File "c:\python34\lib\site-packages\sqlalchemy\pool.py", line 480, in checkout
    rec = pool._do_get()
  File "c:\python34\lib\site-packages\sqlalchemy\pool.py", line 1151, in _do_get
    return self._create_connection()
  File "c:\python34\lib\site-packages\sqlalchemy\pool.py", line 323, in _create_connection
    return _ConnectionRecord(self)
  File "c:\python34\lib\site-packages\sqlalchemy\pool.py", line 449, in __init__
    self.connection = self.__connect()
  File "c:\python34\lib\site-packages\sqlalchemy\pool.py", line 607, in __connect
    connection = self.__pool._invoke_creator(self)
  File "c:\python34\lib\site-packages\sqlalchemy\engine\strategies.py", line 97, in connect
    return dialect.connect(*cargs, **cparams)
  File "c:\python34\lib\site-packages\sqlalchemy\engine\default.py", line 385, in connect
    return self.dbapi.connect(*cargs, **cparams)
sqlalchemy.exc.OperationalError: (sqlite3.OperationalError) unable to open database file

======================================================================
ERROR: test_get_all_meteorites (__main__.TestMeteorites)
----------------------------------------------------------------------
Traceback (most recent call last):
  File "c:\python34\lib\site-packages\sqlalchemy\engine\base.py", line 2074, in _wrap_pool_connect
    return fn()
  File "c:\python34\lib\site-packages\sqlalchemy\pool.py", line 376, in connect
    return _ConnectionFairy._checkout(self)
  File "c:\python34\lib\site-packages\sqlalchemy\pool.py", line 713, in _checkout
    fairy = _ConnectionRecord.checkout(pool)
  File "c:\python34\lib\site-packages\sqlalchemy\pool.py", line 480, in checkout
    rec = pool._do_get()
  File "c:\python34\lib\site-packages\sqlalchemy\pool.py", line 1151, in _do_get
    return self._create_connection()
  File "c:\python34\lib\site-packages\sqlalchemy\pool.py", line 323, in _create_connection
    return _ConnectionRecord(self)
  File "c:\python34\lib\site-packages\sqlalchemy\pool.py", line 449, in __init__
    self.connection = self.__connect()
  File "c:\python34\lib\site-packages\sqlalchemy\pool.py", line 607, in __connect
    connection = self.__pool._invoke_creator(self)
  File "c:\python34\lib\site-packages\sqlalchemy\engine\strategies.py", line 97, in connect
    return dialect.connect(*cargs, **cparams)
  File "c:\python34\lib\site-packages\sqlalchemy\engine\default.py", line 385, in connect
    return self.dbapi.connect(*cargs, **cparams)
sqlite3.OperationalError: unable to open database file

The above exception was the direct cause of the following exception:

Traceback (most recent call last):
  File "app/tests.py", line 12, in setUp
    db.create_all()
  File "c:\python34\lib\site-packages\flask_sqlalchemy\__init__.py", line 972, in create_all
    self._execute_for_all_tables(app, bind, 'create_all')
  File "c:\python34\lib\site-packages\flask_sqlalchemy\__init__.py", line 964, in _execute_for_all_tables
    op(bind=self.get_engine(app, bind), **extra)
  File "c:\python34\lib\site-packages\sqlalchemy\sql\schema.py", line 3695, in create_all
    tables=tables)
  File "c:\python34\lib\site-packages\sqlalchemy\engine\base.py", line 1855, in _run_visitor
    with self._optional_conn_ctx_manager(connection) as conn:
  File "c:\python34\lib\contextlib.py", line 59, in __enter__
    return next(self.gen)
  File "c:\python34\lib\site-packages\sqlalchemy\engine\base.py", line 1848, in _optional_conn_ctx_manager
    with self.contextual_connect() as conn:
  File "c:\python34\lib\site-packages\sqlalchemy\engine\base.py", line 2039, in contextual_connect
    self._wrap_pool_connect(self.pool.connect, None),
  File "c:\python34\lib\site-packages\sqlalchemy\engine\base.py", line 2078, in _wrap_pool_connect
    e, dialect, self)
  File "c:\python34\lib\site-packages\sqlalchemy\engine\base.py", line 1405, in _handle_dbapi_exception_noconnection
    exc_info
  File "c:\python34\lib\site-packages\sqlalchemy\util\compat.py", line 200, in raise_from_cause
    reraise(type(exception), exception, tb=exc_tb, cause=cause)
  File "c:\python34\lib\site-packages\sqlalchemy\util\compat.py", line 183, in reraise
    raise value.with_traceback(tb)
  File "c:\python34\lib\site-packages\sqlalchemy\engine\base.py", line 2074, in _wrap_pool_connect
    return fn()
  File "c:\python34\lib\site-packages\sqlalchemy\pool.py", line 376, in connect
    return _ConnectionFairy._checkout(self)
  File "c:\python34\lib\site-packages\sqlalchemy\pool.py", line 713, in _checkout
    fairy = _ConnectionRecord.checkout(pool)
  File "c:\python34\lib\site-packages\sqlalchemy\pool.py", line 480, in checkout
    rec = pool._do_get()
  File "c:\python34\lib\site-packages\sqlalchemy\pool.py", line 1151, in _do_get
    return self._create_connection()
  File "c:\python34\lib\site-packages\sqlalchemy\pool.py", line 323, in _create_connection
    return _ConnectionRecord(self)
  File "c:\python34\lib\site-packages\sqlalchemy\pool.py", line 449, in __init__
    self.connection = self.__connect()
  File "c:\python34\lib\site-packages\sqlalchemy\pool.py", line 607, in __connect
    connection = self.__pool._invoke_creator(self)
  File "c:\python34\lib\site-packages\sqlalchemy\engine\strategies.py", line 97, in connect
    return dialect.connect(*cargs, **cparams)
  File "c:\python34\lib\site-packages\sqlalchemy\engine\default.py", line 385, in connect
    return self.dbapi.connect(*cargs, **cparams)
sqlalchemy.exc.OperationalError: (sqlite3.OperationalError) unable to open database file

----------------------------------------------------------------------
Ran 9 tests in 0.057s

FAILED (errors=9)
Name                                                                    Stmts   Miss Branch BrPart  Cover   Missing
-------------------------------------------------------------------------------------------------------------------
app\app.py                                                                 96     71     20      1    22%   27-36, 47-57, 63-65, 70-72, 76-78, 82-84, 95, 99-101, 106-156, 159-160, 158->159
app\db.py                                                                  12      0      0      0   100%   
app\models.py                                                              61     24      0      0    61%   37-44, 47, 50-52, 73-77, 80, 100-104, 107
app\requests\__init__.py                                                   26      5      0      0    81%   54, 72-75
app\requests\adapters.py                                                  177    134     46      0    19%   44, 47, 50, 85-98, 101, 107-113, 129-133, 147-157, 169-194, 205-230, 240-253, 261, 276-285, 299, 314-321, 337-437
app\requests\api.py                                                        24     14      0      0    42%   48-54, 64-65, 75-76, 86-87, 99, 110, 121, 131
app\requests\auth.py                                                      133    107     40      0    15%   29-33, 40, 46-47, 50-51, 57-58, 64-70, 74-153, 157-158, 163-193, 197-209
app\requests\certs.py                                                       9      1      2      1    82%   25, 24->25
app\requests\compat.py                                                     54     12      4      2    76%   88-100, 87->88, 103->-5
app\requests\cookies.py                                                   213    156     92      0    19%   17-18, 34-36, 39, 42, 45, 50-56, 62, 65, 68, 72, 75, 78, 82, 86, 90, 105, 108, 111, 121-128, 133-135, 143-151, 180-183, 190-199, 204-205, 210, 215-216, 221, 226-227, 233, 237-241, 245-249, 254-259, 264-269, 276, 283, 287, 290-292, 296-300, 307-313, 320-331, 335-338, 342-344, 348-350, 359-385, 391-398, 423-432, 441-454
app\requests\exceptions.py                                                 26      6      2      0    71%   21-27
app\requests\hooks.py                                                      18     14     10      0    14%   21-24, 32-45
app\requests\models.py                                                    404    338    176      0    11%   57-72, 83-99, 110-158, 165-171, 178-182, 222-240, 243, 247-260, 284-295, 302-312, 315, 318-325, 329-331, 340-403, 408-411, 420-466, 469-478, 484-500, 505-512, 516-517, 539-580, 585-588, 594-599, 602, 606, 610, 614, 618-622, 629, 634, 639, 651-685, 693-714, 720-738, 754-776, 784-799, 805-817, 822-831, 839
app\requests\packages\__init__.py                                           2      0      0      0   100%   
app\requests\packages\chardet\__init__.py                                  11      8      2      0    23%   23-32
app\requests\packages\urllib3\__init__.py                                  33     12      0      0    64%   30-33, 46-52, 66
app\requests\packages\urllib3\_collections.py                              92     62     25      0    26%   4-10, 15-16, 43-47, 51-54, 57-69, 72-76, 79-80, 83, 86-93, 96-97, 145-148, 159, 164, 167-171, 174-177, 181-182, 185, 188, 191, 194-195, 198
app\requests\packages\urllib3\connection.py                               110     66     22      1    34%   10-11, 23-27, 33-35, 100-118, 125-141, 144-152, 155-156, 165-173, 176-178, 195-200, 204-255, 259->-1
app\requests\packages\urllib3\connectionpool.py                           262    213     88      0    14%   11-13, 64-69, 72, 147-180, 186-193, 207-231, 247-261, 267, 271-279, 284-296, 314-365, 372-381, 388-400, 485-617, 650-659, 667-692, 698-717, 723-730, 757-761
app\requests\packages\urllib3\contrib\__init__.py                           0      0      0      0   100%   
app\requests\packages\urllib3\contrib\pyopenssl.py                        142    139     40      0     2%   51, 53-303
app\requests\packages\urllib3\exceptions.py                                63     15      0      0    76%   17-18, 22, 28-29, 33, 73-78, 85-87, 135-138
app\requests\packages\urllib3\fields.py                                    68     56     29      0    12%   16-18, 34-46, 63-68, 88-102, 113, 126-135, 141-154, 170-177
app\requests\packages\urllib3\filepost.py                                  38     27     20      0    19%   17, 28-37, 52-55, 69-93
app\requests\packages\urllib3\packages\__init__.py                          2      0      0      0   100%   
app\requests\packages\urllib3\packages\six.py                             217    120     74      9    39%   42-64, 100, 103, 112, 121-124, 191, 196-202, 216-224, 229-231, 237, 242-252, 265, 269, 273, 278, 280, 282-283, 291-297, 308-310, 317-378, 385, 33->42, 95->100, 110->121, 111->112, 205->216, 235->244, 276->291, 281->282, 302->317
app\requests\packages\urllib3\packages\ssl_match_hostname\__init__.py       8      5      0      0    38%   4-10
app\requests\packages\urllib3\poolmanager.py                              105     77     32      0    20%   5-6, 62-64, 75-82, 91, 101-119, 130-131, 142-174, 207-224, 228-232, 240-248, 252-261, 265
app\requests\packages\urllib3\request.py                                   36     25     12      0    23%   3-4, 44, 49, 63-70, 79-81, 121-141
app\requests\packages\urllib3\response.py                                 157    125     64      0    14%   16-18, 21, 24-36, 40-43, 79-104, 114-117, 120-124, 129-133, 141, 166-237, 255-259, 271-277, 288, 291, 295-296, 300-307, 310-315, 319-320, 324, 328-333
app\requests\packages\urllib3\util\__init__.py                              7      0      0      0   100%   
app\requests\packages\urllib3\util\connection.py                           54     44     26      0    12%   8-9, 22-43, 62-89, 93-97
app\requests\packages\urllib3\util\request.py                              23     19     16      0    10%   44-71
app\requests\packages\urllib3\util\response.py                             10      9      0      0    10%   9-22
app\requests\packages\urllib3\util\retry.py                                98     67     38      1    24%   121-122, 132-142, 147-156, 163-167, 175-178, 184, 190, 195-198, 202-207, 220-275, 279, 120->121
app\requests\packages\urllib3\util\ssl_.py                                112     90     36      0    15%   17-18, 23-25, 29-30, 38-82, 97-116, 132-141, 148-157, 195-215, 234-254
app\requests\packages\urllib3\util\timeout.py                              57     41     20      0    21%   16, 95-98, 101, 115-136, 152, 166, 175-178, 188-191, 203-209, 228-240
app\requests\packages\urllib3\util\url.py                                  92     78     52      0    10%   18, 24, 29-34, 39-41, 62-81, 84, 102-116, 141-205, 211-212
app\requests\sessions.py                                                  262    216     94      0    13%   49-72, 82-88, 96-198, 206-223, 236-260, 287-334, 337, 340, 351-380, 432-463, 472-473, 482-483, 492-493, 504, 514, 524, 533, 539-612, 617-635, 640-646, 650-651, 658-662, 665-667, 670-676, 682
app\requests\status_codes.py                                                8      0      6      0   100%   
app\requests\structures.py                                                 39     19      8      0    43%   43-46, 51, 54, 57, 60, 63, 67, 74-79, 83, 86, 96, 101, 104
app\requests\utils.py                                                     324    266    138      0    13%   43-46, 50-66, 72-112, 117-119, 136-142, 158-167, 193-198, 223-232, 243-257, 266-271, 281-283, 291-301, 312-323, 329-341, 346-349, 363-384, 397-412, 424, 433-437, 445-446, 450-454, 459-474, 481-520, 524-527, 532-556, 562, 577-601, 614-636, 642-650, 656-663, 672-682, 689-697
app\tests.py                                                               96     60      2      1    38%   13-17, 22-23, 27-31, 35-42, 45-46, 55-59, 64-65, 69-73, 77-84, 87-88, 98-102, 107-108, 112-116, 120-127, 130-131, 133->-1
-------------------------------------------------------------------------------------------------------------------
TOTAL                                                                    3781   2741   1236     16    21%   
